model
size = 10 16 10, scale = 0.05, origin = -y
material 
  colors = A:#A4A4F4 B:#C5C5FF C:#9774CE D:#C5ADEC E:#302F2B
voxels
---------- ---AAAA--- --A----A-- -A------A- -A------A- -A------A- -A------A- --AA--AA-- ----AA---- ---------- ---------- ---------- ---------- ---------- ---------- ---------- 
---BBBB--- -BBAAAABB- -BA----AB- BA------AB BA------AB BAE-EE-EAB BA------AB -BAA--AAB- -BBBAABBB- ----BB---- ----C----- -----C---- ---DC-D--- -DCD--DCD- DC------CD ---------- 
---------- ---------- ---------- ---------- ---------- ---------- ---------- ---------- ---------- ---------- ---------- ---------- ---------- ---------- ---------- C--------C 
---------- ---------- ---------- ---------- ---------- ---------- ---------- ---------- ---------- ---------- ---------- ---------- ---------- ---------- ---------- D--------D 
---------- ---------- ---------- ---------- ---------- ---------- ---------- ---------- ---------- ---------- ---------- ---------- ---------- ---------- ---------- C--------C 
---------- ---------- ---------- ---------- ---------- ---------- ---------- ---------- ---------- ---------- ---------- ---------- ---------- ---------- ---------- -D------D- 
---------- ---------- ---------- ---------- ---------- ---------- ---------- ---------- ---------- ---------- ---------- ---------- ---------- ---------- ---------- -C------C- 
---------- ---------- ---------- ---------- ---------- ---------- ---------- ---------- ---------- ---------- ---------- ---------- ---------- ---------- ---------- --D----D-- 
---------- ---------- ---------- ---------- ---------- ---------- ---------- ---------- ---------- ---------- ---------- ---------- ---------- ---------- ---------- --C----C-- 
---------- ---------- ---------- ---------- ---------- ---------- ---------- ---------- ---------- ---------- ---------- ---------- ---------- ---------- ---------- ---DCCD--- 
